<?xml version='1.0'?>
<sdf version='1.6'>
		<model name="ur5e_gripper">
			<self_collide>true</self_collide>
			<pose>0.0 0.0 0.0 0.0 0.0 0.0</pose>
			<!-- Start of parts of the pmodel ur5e_gripper -->
			<!-- End of parts of the pmodel ur5e_gripper -->
			
			<!-- Start of links of the pmodel ur5e_gripper -->
			<!-- link full name is ur5e_gripper::base_link -->
			<link name="1-base_link">
					<pose>0.0 0.0 0.0 0.0 0.0 3.1414999961853027</pose>
					<inertial>
						<pose>0.0 0.0 0.0 0.0 0.0 0.0</pose>
						<inertia>
							<ixx>1.0</ixx>
							<ixy>0.0</ixy>
							<ixz>0.0</ixz>
							<iyy>1.0</iyy>
							<iyz>0.0</iyz>
							<izz>1.0</izz>
						</inertia>
						<mass>4.0</mass>
					</inertial>
					<!-- body full name is ur5e_gripper::base_link::base_link_collision -->
					<collision name="1--base_link_collision">
						<laser_retro>0.0</laser_retro>
						<pose>0.0 0.0 0.0 0.0 0.0 0.0</pose>
						<geometry>
							<cylinder>
								<radius>0.07500000298023224</radius>
								<length>0.09880000352859497</length>
							</cylinder>
						</geometry>
						<surface>
							<bounce>
								<restitution_coefficient>0.0</restitution_coefficient>
								<threshold>100000.0</threshold>
							</bounce>
							<friction>
								<ode>
									<mu>1.0</mu>
									<mu2>1.0</mu2>
									<fdir1>0.0 0.0 0.0</fdir1>
									<slip1>0.0</slip1>
									<slip2>0.0</slip2>
								</ode>
								<torsional>
									<coefficient>1.0</coefficient>
									<surface_radius>0.0</surface_radius>
								</torsional>
							</friction>
						</surface>
					</collision>
					<visual name="1--base_link_collision">
						<laser_retro>0.0</laser_retro>
						<pose>0.0 0.0 0.0 0.0 0.0 0.0</pose>
						<geometry>
							<cylinder>
								<radius>0.07500000298023224</radius>
								<length>0.09880000352859497</length>
							</cylinder>
						</geometry>
						<surface>
							<bounce>
								<restitution_coefficient>0.0</restitution_coefficient>
								<threshold>100000.0</threshold>
							</bounce>
							<friction>
								<ode>
									<mu>1.0</mu>
									<mu2>1.0</mu2>
									<fdir1>0.0 0.0 0.0</fdir1>
									<slip1>0.0</slip1>
									<slip2>0.0</slip2>
								</ode>
								<torsional>
									<coefficient>1.0</coefficient>
									<surface_radius>0.0</surface_radius>
								</torsional>
							</friction>
						</surface>
					</visual>
					<!-- WARNING: Annotation not found for the sensor FSJ1. The SDF generator relies on annotations to specify aspects of the 
					  	 sensor that are accounted for in the equations. --> If you wish to reflect these aspects in SDF,
					     please add an appropriate annotation to the sensor. --> 
			</link>	
			<!-- link full name is ur5e_gripper::shoulder_link -->
			<link name="2-shoulder_link">
					<pose>0.0 0.0 0.08915899693965912 0.0 0.0 0.0</pose>
					<inertial>
						<pose>0.0 0.001930000027641654 -0.025609999895095825 0.0 0.0 0.0</pose>
						<inertia>
							<ixx>1.0</ixx>
							<ixy>0.0</ixy>
							<ixz>0.0</ixz>
							<iyy>1.0</iyy>
							<iyz>0.0</iyz>
							<izz>1.0</izz>
						</inertia>
						<mass>3.760999917984009</mass>
					</inertial>
					<!-- body full name is ur5e_gripper::shoulder_link::shoulder_link_collision -->
					<collision name="2--shoulder_link_collision">
						<laser_retro>0.0</laser_retro>
						<pose>0.0 0.0 0.015599995851516724 0.0 0.0 1.5707499980926514</pose>
						<geometry>
							<cylinder>
								<radius>0.07000000029802322</radius>
								<length>0.12999999523162842</length>
							</cylinder>
						</geometry>
						<surface>
							<bounce>
								<restitution_coefficient>0.0</restitution_coefficient>
								<threshold>100000.0</threshold>
							</bounce>
							<friction>
								<ode>
									<mu>1.0</mu>
									<mu2>1.0</mu2>
									<fdir1>0.0 0.0 0.0</fdir1>
									<slip1>0.0</slip1>
									<slip2>0.0</slip2>
								</ode>
								<torsional>
									<coefficient>1.0</coefficient>
									<surface_radius>0.0</surface_radius>
								</torsional>
							</friction>
						</surface>
					</collision>
					<visual name="2--shoulder_link_collision">
						<laser_retro>0.0</laser_retro>
						<pose>0.0 0.0 0.015599995851516724 0.0 0.0 1.5707499980926514</pose>
						<geometry>
							<cylinder>
								<radius>0.07000000029802322</radius>
								<length>0.12999999523162842</length>
							</cylinder>
						</geometry>
						<surface>
							<bounce>
								<restitution_coefficient>0.0</restitution_coefficient>
								<threshold>100000.0</threshold>
							</bounce>
							<friction>
								<ode>
									<mu>1.0</mu>
									<mu2>1.0</mu2>
									<fdir1>0.0 0.0 0.0</fdir1>
									<slip1>0.0</slip1>
									<slip2>0.0</slip2>
								</ode>
								<torsional>
									<coefficient>1.0</coefficient>
									<surface_radius>0.0</surface_radius>
								</torsional>
							</friction>
						</surface>
					</visual>
					<!-- WARNING: Annotation not found for the sensor FSJ2. The SDF generator relies on annotations to specify aspects of the 
					  	 sensor that are accounted for in the equations. --> If you wish to reflect these aspects in SDF,
					     please add an appropriate annotation to the sensor. --> 
			</link>	
			<!-- link full name is ur5e_gripper::upper_arm_link -->
			<link name="3-upper_arm_link">
					<pose>0.0 0.1358499974012375 0.08915899693965912 3.1414999961853027 1.5707499980926514 3.1414999961853027</pose>
					<inertial>
						<pose>0.0 -0.02420100010931492 0.21250000596046448 0.0 0.0 0.0</pose>
						<inertia>
							<ixx>1.0</ixx>
							<ixy>0.0</ixy>
							<ixz>0.0</ixz>
							<iyy>1.0</iyy>
							<iyz>0.0</iyz>
							<izz>1.0</izz>
						</inertia>
						<mass>8.057999610900879</mass>
					</inertial>
					<!-- body full name is ur5e_gripper::upper_arm_link::upper_arm_link_collision -->
					<collision name="3--upper_arm_link_collision">
						<laser_retro>0.0</laser_retro>
						<pose>0.0 0.0 0.20500001311302185 0.0 0.0 0.0</pose>
						<geometry>
							<cylinder>
								<radius>0.042500000447034836</radius>
								<length>0.5400000214576721</length>
							</cylinder>
						</geometry>
						<surface>
							<bounce>
								<restitution_coefficient>0.0</restitution_coefficient>
								<threshold>100000.0</threshold>
							</bounce>
							<friction>
								<ode>
									<mu>1.0</mu>
									<mu2>1.0</mu2>
									<fdir1>0.0 0.0 0.0</fdir1>
									<slip1>0.0</slip1>
									<slip2>0.0</slip2>
								</ode>
								<torsional>
									<coefficient>1.0</coefficient>
									<surface_radius>0.0</surface_radius>
								</torsional>
							</friction>
						</surface>
					</collision>
					<visual name="3--upper_arm_link_collision">
						<laser_retro>0.0</laser_retro>
						<pose>0.0 0.0 0.20500001311302185 0.0 0.0 0.0</pose>
						<geometry>
							<cylinder>
								<radius>0.042500000447034836</radius>
								<length>0.5400000214576721</length>
							</cylinder>
						</geometry>
						<surface>
							<bounce>
								<restitution_coefficient>0.0</restitution_coefficient>
								<threshold>100000.0</threshold>
							</bounce>
							<friction>
								<ode>
									<mu>1.0</mu>
									<mu2>1.0</mu2>
									<fdir1>0.0 0.0 0.0</fdir1>
									<slip1>0.0</slip1>
									<slip2>0.0</slip2>
								</ode>
								<torsional>
									<coefficient>1.0</coefficient>
									<surface_radius>0.0</surface_radius>
								</torsional>
							</friction>
						</surface>
					</visual>
					<!-- WARNING: Annotation not found for the sensor FSJ3. The SDF generator relies on annotations to specify aspects of the 
					  	 sensor that are accounted for in the equations. --> If you wish to reflect these aspects in SDF,
					     please add an appropriate annotation to the sensor. --> 
			</link>	
			<!-- link full name is ur5e_gripper::forearm_link -->
			<link name="4-forearm_link">
					<pose>0.42500001192092896 0.01614999957382679 0.08915899693965912 3.1414999961853027 1.5707499980926514 3.1414999961853027</pose>
					<inertial>
						<pose>0.0 0.0 0.0 0.0 0.0 0.0</pose>
						<inertia>
							<ixx>1.0</ixx>
							<ixy>0.0</ixy>
							<ixz>0.0</ixz>
							<iyy>1.0</iyy>
							<iyz>0.0</iyz>
							<izz>1.0</izz>
						</inertia>
						<mass>2.8459999561309814</mass>
					</inertial>
					<!-- body full name is ur5e_gripper::forearm_link::forearm_link_collision -->
					<collision name="4--forearm_link_collision">
						<laser_retro>0.0</laser_retro>
						<pose>0.0 0.0 0.1274999976158142 0.0 0.0 0.0</pose>
						<geometry>
							<cylinder>
								<radius>0.03750000149011612</radius>
								<length>0.3709999918937683</length>
							</cylinder>
						</geometry>
						<surface>
							<bounce>
								<restitution_coefficient>0.0</restitution_coefficient>
								<threshold>100000.0</threshold>
							</bounce>
							<friction>
								<ode>
									<mu>1.0</mu>
									<mu2>1.0</mu2>
									<fdir1>0.0 0.0 0.0</fdir1>
									<slip1>0.0</slip1>
									<slip2>0.0</slip2>
								</ode>
								<torsional>
									<coefficient>1.0</coefficient>
									<surface_radius>0.0</surface_radius>
								</torsional>
							</friction>
						</surface>
					</collision>
					<visual name="4--forearm_link_collision">
						<laser_retro>0.0</laser_retro>
						<pose>0.0 0.0 0.1274999976158142 0.0 0.0 0.0</pose>
						<geometry>
							<cylinder>
								<radius>0.03750000149011612</radius>
								<length>0.3709999918937683</length>
							</cylinder>
						</geometry>
						<surface>
							<bounce>
								<restitution_coefficient>0.0</restitution_coefficient>
								<threshold>100000.0</threshold>
							</bounce>
							<friction>
								<ode>
									<mu>1.0</mu>
									<mu2>1.0</mu2>
									<fdir1>0.0 0.0 0.0</fdir1>
									<slip1>0.0</slip1>
									<slip2>0.0</slip2>
								</ode>
								<torsional>
									<coefficient>1.0</coefficient>
									<surface_radius>0.0</surface_radius>
								</torsional>
							</friction>
						</surface>
					</visual>
					<!-- WARNING: Annotation not found for the sensor FSJ4. The SDF generator relies on annotations to specify aspects of the 
					  	 sensor that are accounted for in the equations. --> If you wish to reflect these aspects in SDF,
					     please add an appropriate annotation to the sensor. --> 
			</link>	
			<!-- link full name is ur5e_gripper::wrist_1_link -->
			<link name="5-wrist_1_link">
					<pose>0.8172500133514404 0.01614999957382679 0.08915899693965912 3.1414999961853027 0.0 3.1414999961853027</pose>
					<inertial>
						<pose>0.0 0.0 0.0 0.0 0.0 0.0</pose>
						<inertia>
							<ixx>1.0</ixx>
							<ixy>0.0</ixy>
							<ixz>0.0</ixz>
							<iyy>1.0</iyy>
							<iyz>0.0</iyz>
							<izz>1.0</izz>
						</inertia>
						<mass>1.3700000047683716</mass>
					</inertial>
					<!-- body full name is ur5e_gripper::wrist_1_link::wrist_1_link_collision -->
					<collision name="5--wrist_1_link_collision">
						<laser_retro>0.0</laser_retro>
						<pose>0.0 0.0 -0.001500002108514309 1.5707499980926514 0.0 0.0</pose>
						<geometry>
							<cylinder>
								<radius>0.03750000149011612</radius>
								<length>0.10199999809265137</length>
							</cylinder>
						</geometry>
						<surface>
							<bounce>
								<restitution_coefficient>0.0</restitution_coefficient>
								<threshold>100000.0</threshold>
							</bounce>
							<friction>
								<ode>
									<mu>1.0</mu>
									<mu2>1.0</mu2>
									<fdir1>0.0 0.0 0.0</fdir1>
									<slip1>0.0</slip1>
									<slip2>0.0</slip2>
								</ode>
								<torsional>
									<coefficient>1.0</coefficient>
									<surface_radius>0.0</surface_radius>
								</torsional>
							</friction>
						</surface>
					</collision>
					<visual name="5--wrist_1_link_collision">
						<laser_retro>0.0</laser_retro>
						<pose>0.0 0.0 -0.001500002108514309 1.5707499980926514 0.0 0.0</pose>
						<geometry>
							<cylinder>
								<radius>0.03750000149011612</radius>
								<length>0.10199999809265137</length>
							</cylinder>
						</geometry>
						<surface>
							<bounce>
								<restitution_coefficient>0.0</restitution_coefficient>
								<threshold>100000.0</threshold>
							</bounce>
							<friction>
								<ode>
									<mu>1.0</mu>
									<mu2>1.0</mu2>
									<fdir1>0.0 0.0 0.0</fdir1>
									<slip1>0.0</slip1>
									<slip2>0.0</slip2>
								</ode>
								<torsional>
									<coefficient>1.0</coefficient>
									<surface_radius>0.0</surface_radius>
								</torsional>
							</friction>
						</surface>
					</visual>
					<!-- WARNING: Annotation not found for the sensor FSJ5. The SDF generator relies on annotations to specify aspects of the 
					  	 sensor that are accounted for in the equations. --> If you wish to reflect these aspects in SDF,
					     please add an appropriate annotation to the sensor. --> 
			</link>	
			<!-- link full name is ur5e_gripper::wrist_2_link -->
			<link name="6-wrist_2_link">
					<pose>0.8172500133514404 0.1091499999165535 0.08915899693965912 3.1414999961853027 0.0 3.1414999961853027</pose>
					<inertial>
						<pose>0.0 0.0 0.0 0.0 0.0 0.0</pose>
						<inertia>
							<ixx>1.0</ixx>
							<ixy>0.0</ixy>
							<ixz>0.0</ixz>
							<iyy>1.0</iyy>
							<iyz>0.0</iyz>
							<izz>1.0</izz>
						</inertia>
						<mass>1.2999999523162842</mass>
					</inertial>
					<!-- body full name is ur5e_gripper::wrist_2_link::wrist_2_link_collision -->
					<collision name="6--wrist_2_link_collision">
						<laser_retro>0.0</laser_retro>
						<pose>0.0 0.0 -0.008999999612569809 0.0 0.0 0.0</pose>
						<geometry>
							<cylinder>
								<radius>0.03750000149011612</radius>
								<length>0.10199999809265137</length>
							</cylinder>
						</geometry>
						<surface>
							<bounce>
								<restitution_coefficient>0.0</restitution_coefficient>
								<threshold>100000.0</threshold>
							</bounce>
							<friction>
								<ode>
									<mu>1.0</mu>
									<mu2>1.0</mu2>
									<fdir1>0.0 0.0 0.0</fdir1>
									<slip1>0.0</slip1>
									<slip2>0.0</slip2>
								</ode>
								<torsional>
									<coefficient>1.0</coefficient>
									<surface_radius>0.0</surface_radius>
								</torsional>
							</friction>
						</surface>
					</collision>
					<visual name="6--wrist_2_link_collision">
						<laser_retro>0.0</laser_retro>
						<pose>0.0 0.0 -0.008999999612569809 0.0 0.0 0.0</pose>
						<geometry>
							<cylinder>
								<radius>0.03750000149011612</radius>
								<length>0.10199999809265137</length>
							</cylinder>
						</geometry>
						<surface>
							<bounce>
								<restitution_coefficient>0.0</restitution_coefficient>
								<threshold>100000.0</threshold>
							</bounce>
							<friction>
								<ode>
									<mu>1.0</mu>
									<mu2>1.0</mu2>
									<fdir1>0.0 0.0 0.0</fdir1>
									<slip1>0.0</slip1>
									<slip2>0.0</slip2>
								</ode>
								<torsional>
									<coefficient>1.0</coefficient>
									<surface_radius>0.0</surface_radius>
								</torsional>
							</friction>
						</surface>
					</visual>
					<!-- WARNING: Annotation not found for the sensor FSJ6. The SDF generator relies on annotations to specify aspects of the 
					  	 sensor that are accounted for in the equations. --> If you wish to reflect these aspects in SDF,
					     please add an appropriate annotation to the sensor. --> 
			</link>	
			<!-- link full name is ur5e_gripper::wrist_3_link -->
			<link name="7-wrist_3_link">
					<pose>0.8172500133514404 0.1091499999165535 -0.005491000134497881 3.1414999961853027 0.0 3.1414999961853027</pose>
					<inertial>
						<pose>0.0 0.0 0.0 0.0 0.0 0.0</pose>
						<inertia>
							<ixx>1.0</ixx>
							<ixy>0.0</ixy>
							<ixz>0.0</ixz>
							<iyy>1.0</iyy>
							<iyz>0.0</iyz>
							<izz>1.0</izz>
						</inertia>
						<mass>0.36500000953674316</mass>
					</inertial>
					<!-- body full name is ur5e_gripper::wrist_3_link::wrist_3_link_collision -->
					<collision name="7--wrist_3_link_collision">
						<laser_retro>0.0</laser_retro>
						<pose>0.0 0.0 0.004749998450279236 1.5707499980926514 0.0 0.0</pose>
						<geometry>
							<cylinder>
								<radius>0.03750000149011612</radius>
								<length>0.04699999839067459</length>
							</cylinder>
						</geometry>
						<surface>
							<bounce>
								<restitution_coefficient>0.0</restitution_coefficient>
								<threshold>100000.0</threshold>
							</bounce>
							<friction>
								<ode>
									<mu>1.0</mu>
									<mu2>1.0</mu2>
									<fdir1>0.0 0.0 0.0</fdir1>
									<slip1>0.0</slip1>
									<slip2>0.0</slip2>
								</ode>
								<torsional>
									<coefficient>1.0</coefficient>
									<surface_radius>0.0</surface_radius>
								</torsional>
							</friction>
						</surface>
					</collision>
					<visual name="7--wrist_3_link_collision">
						<laser_retro>0.0</laser_retro>
						<pose>0.0 0.0 0.004749998450279236 1.5707499980926514 0.0 0.0</pose>
						<geometry>
							<cylinder>
								<radius>0.03750000149011612</radius>
								<length>0.04699999839067459</length>
							</cylinder>
						</geometry>
						<surface>
							<bounce>
								<restitution_coefficient>0.0</restitution_coefficient>
								<threshold>100000.0</threshold>
							</bounce>
							<friction>
								<ode>
									<mu>1.0</mu>
									<mu2>1.0</mu2>
									<fdir1>0.0 0.0 0.0</fdir1>
									<slip1>0.0</slip1>
									<slip2>0.0</slip2>
								</ode>
								<torsional>
									<coefficient>1.0</coefficient>
									<surface_radius>0.0</surface_radius>
								</torsional>
							</friction>
						</surface>
					</visual>
			</link>	
			<!-- link full name is ur5e_gripper::link_2fg7_base -->
			<link name="8-link_2fg7_base">
					<pose>0.8172500133514404 0.22165000438690186 -0.005491000134497881 -1.5707499980926514 0.0 0.0</pose>
					<inertial>
						<pose>0.0 0.0 0.0 0.0 0.0 0.0</pose>
						<inertia>
							<ixx>1.0</ixx>
							<ixy>0.0</ixy>
							<ixz>0.0</ixz>
							<iyy>1.0</iyy>
							<iyz>0.0</iyz>
							<izz>1.0</izz>
						</inertia>
						<mass>1.2646523714065552</mass>
					</inertial>
					<!-- body full name is ur5e_gripper::link_2fg7_base::link_2fg7_box -->
					<collision name="8--link_2fg7_box">
						<laser_retro>0.0</laser_retro>
						<pose>0.0 0.0 0.0 0.0 0.0 0.0</pose>
						<geometry>
							<box> 
								<size>0.07100000232458115 0.09000000357627869 0.1445000022649765</size>
							</box>
						</geometry>
						<surface>
							<bounce>
								<restitution_coefficient>0.0</restitution_coefficient>
								<threshold>100000.0</threshold>
							</bounce>
							<friction>
								<ode>
									<mu>1.0</mu>
									<mu2>1.0</mu2>
									<fdir1>0.0 0.0 0.0</fdir1>
									<slip1>0.0</slip1>
									<slip2>0.0</slip2>
								</ode>
								<torsional>
									<coefficient>1.0</coefficient>
									<surface_radius>0.0</surface_radius>
								</torsional>
							</friction>
						</surface>
					</collision>
					<visual name="8--link_2fg7_box">
						<laser_retro>0.0</laser_retro>
						<pose>0.0 0.0 0.0 0.0 0.0 0.0</pose>
						<geometry>
							<box> 
								<size>0.07100000232458115 0.09000000357627869 0.1445000022649765</size>
							</box>
						</geometry>
						<surface>
							<bounce>
								<restitution_coefficient>0.0</restitution_coefficient>
								<threshold>100000.0</threshold>
							</bounce>
							<friction>
								<ode>
									<mu>1.0</mu>
									<mu2>1.0</mu2>
									<fdir1>0.0 0.0 0.0</fdir1>
									<slip1>0.0</slip1>
									<slip2>0.0</slip2>
								</ode>
								<torsional>
									<coefficient>1.0</coefficient>
									<surface_radius>0.0</surface_radius>
								</torsional>
							</friction>
						</surface>
					</visual>
					<!-- WARNING: Annotation not found for the actuator GR1. RoboSim actuators have no explicit counterparts in SDF, 
						 so the generator must rely on annotations to produce something meaningful in SDF. If you wish to reflect these aspects in SDF,
						 please add an appropriate annotation to the actuator. -->
			</link>	
			<!-- link full name is ur5e_gripper::rightFingerLink -->
			<link name="9-rightFingerLink">
					<pose>0.8172500133514404 0.299156004562974 -0.037730001378804445 -1.5707499980926514 0.0 0.0</pose>
					<inertial>
						<pose>0.0 0.0 0.0 0.0 0.0 0.0</pose>
						<inertia>
							<ixx>1.0</ixx>
							<ixy>0.0</ixy>
							<ixz>0.0</ixz>
							<iyy>1.0</iyy>
							<iyz>0.0</iyz>
							<izz>1.0</izz>
						</inertia>
						<mass>0.023219384253025055</mass>
					</inertial>
					<!-- body full name is ur5e_gripper::rightFingerLink::rightFingerBody -->
					<collision name="9--rightFingerBody">
						<laser_retro>0.0</laser_retro>
						<pose>0.0 0.0 0.0 0.0 0.0 0.0</pose>
						<geometry>
							<box> 
								<size>0.03200000151991844 0.004999999888241291 0.04500000178813934</size>
							</box>
						</geometry>
						<surface>
							<bounce>
								<restitution_coefficient>0.0</restitution_coefficient>
								<threshold>100000.0</threshold>
							</bounce>
							<friction>
								<ode>
									<mu>1.0</mu>
									<mu2>1.0</mu2>
									<fdir1>0.0 0.0 0.0</fdir1>
									<slip1>0.0</slip1>
									<slip2>0.0</slip2>
								</ode>
								<torsional>
									<coefficient>1.0</coefficient>
									<surface_radius>0.0</surface_radius>
								</torsional>
							</friction>
						</surface>
					</collision>
					<visual name="9--rightFingerBody">
						<laser_retro>0.0</laser_retro>
						<pose>0.0 0.0 0.0 0.0 0.0 0.0</pose>
						<geometry>
							<box> 
								<size>0.03200000151991844 0.004999999888241291 0.04500000178813934</size>
							</box>
						</geometry>
						<surface>
							<bounce>
								<restitution_coefficient>0.0</restitution_coefficient>
								<threshold>100000.0</threshold>
							</bounce>
							<friction>
								<ode>
									<mu>1.0</mu>
									<mu2>1.0</mu2>
									<fdir1>0.0 0.0 0.0</fdir1>
									<slip1>0.0</slip1>
									<slip2>0.0</slip2>
								</ode>
								<torsional>
									<coefficient>1.0</coefficient>
									<surface_radius>0.0</surface_radius>
								</torsional>
							</friction>
						</surface>
					</visual>
			</link>	
			<!-- link full name is ur5e_gripper::leftFingerLink -->
			<link name="10-leftFingerLink">
					<pose>0.8172500133514404 0.299156004562974 0.026748001109808683 -1.5707499980926514 0.0 0.0</pose>
					<inertial>
						<pose>0.0 0.0 0.0 0.0 0.0 0.0</pose>
						<inertia>
							<ixx>1.0</ixx>
							<ixy>0.0</ixy>
							<ixz>0.0</ixz>
							<iyy>1.0</iyy>
							<iyz>0.0</iyz>
							<izz>1.0</izz>
						</inertia>
						<mass>0.023219384253025055</mass>
					</inertial>
					<!-- body full name is ur5e_gripper::leftFingerLink::leftFingerBody -->
					<collision name="10--leftFingerBody">
						<laser_retro>0.0</laser_retro>
						<pose>0.0 0.0 0.0 0.0 0.0 0.0</pose>
						<geometry>
							<box> 
								<size>0.03200000151991844 0.004999999888241291 0.04500000178813934</size>
							</box>
						</geometry>
						<surface>
							<bounce>
								<restitution_coefficient>0.0</restitution_coefficient>
								<threshold>100000.0</threshold>
							</bounce>
							<friction>
								<ode>
									<mu>1.0</mu>
									<mu2>1.0</mu2>
									<fdir1>0.0 0.0 0.0</fdir1>
									<slip1>0.0</slip1>
									<slip2>0.0</slip2>
								</ode>
								<torsional>
									<coefficient>1.0</coefficient>
									<surface_radius>0.0</surface_radius>
								</torsional>
							</friction>
						</surface>
					</collision>
					<visual name="10--leftFingerBody">
						<laser_retro>0.0</laser_retro>
						<pose>0.0 0.0 0.0 0.0 0.0 0.0</pose>
						<geometry>
							<box> 
								<size>0.03200000151991844 0.004999999888241291 0.04500000178813934</size>
							</box>
						</geometry>
						<surface>
							<bounce>
								<restitution_coefficient>0.0</restitution_coefficient>
								<threshold>100000.0</threshold>
							</bounce>
							<friction>
								<ode>
									<mu>1.0</mu>
									<mu2>1.0</mu2>
									<fdir1>0.0 0.0 0.0</fdir1>
									<slip1>0.0</slip1>
									<slip2>0.0</slip2>
								</ode>
								<torsional>
									<coefficient>1.0</coefficient>
									<surface_radius>0.0</surface_radius>
								</torsional>
							</friction>
						</surface>
					</visual>
			</link>	
			<!-- End of links of the pmodel ur5e_gripper -->
			
			<!-- Start of joints of the pmodel ur5e_gripper -->
			<!-- Full name of joint: ur5e_gripper::shoulder_link::shoulder_lift_joint from ur5e_gripper::shoulder_link to ur5e_gripper::upper_arm_link-->
			<joint name="11-shoulder_lift_joint" type="revolute">
				<pose>-2.8267410634441603E-10 -0.06584999710321428 -6.547961940728004E-15 3.1415926514434447 -1.5707499980928503 3.1415926514434447</pose>
				<parent>2-shoulder_link</parent>
				<child>3-upper_arm_link</child>
				<!-- WARNING: The SDF generator relies on annotations of the joint 11-shoulder_lift_joint to specify in SDF aspects of the joint that are
					 accounted for in the equations. -->
				<axis>
					<xyz>0 1 0</xyz>
					<dynamics>
						<damping>10</damping>
					</dynamics>
					<limit>
						<lower>-6.2829999923706055</lower>
						<upper>6.2829999923706055</upper>
						<velocity>1.5707499980926514</velocity>
						<effort>1000</effort>
					</limit>
				</axis>
				<!-- WARNING: Annotation not found for the actuator M2. RoboSim actuators have no explicit counterparts in SDF, 
					 so the generator must rely on annotations to produce something meaningful in SDF. If you wish to reflect these aspects in SDF,
					 please add an appropriate annotation to the actuator. -->
			</joint>
			<!-- Full name of joint: ur5e_gripper::link_2fg7_base::leftFingerGripper from ur5e_gripper::link_2fg7_base to ur5e_gripper::leftFingerLink-->
			<joint name="12-leftFingerGripper" type="prismatic">
				<pose>0.0 -3.590787001163387E-6 -0.005257492551495269 -1.5707499980926514 -0.0 0.0</pose>
				<parent>8-link_2fg7_base</parent>
				<child>10-leftFingerLink</child>
				<!-- WARNING: The SDF generator relies on annotations of the joint 12-leftFingerGripper to specify in SDF aspects of the joint that are
					 accounted for in the equations. -->
				<axis>
					<xyz>0 0 -1</xyz>
					<dynamics>
						<damping>1000</damping>
					</dynamics>
					<limit>
						<lower>-6.2829999923706055</lower>
						<upper>6.2829999923706055</upper>
						<velocity>1</velocity>
						<effort>1000</effort>
					</limit>
				</axis>
				<!-- WARNING: Annotation not found for the actuator leftFingerMotor. RoboSim actuators have no explicit counterparts in SDF, 
					 so the generator must rely on annotations to produce something meaningful in SDF. If you wish to reflect these aspects in SDF,
					 please add an appropriate annotation to the actuator. -->
			</joint>
			<!-- Full name of joint: ur5e_gripper::link_2fg7_base::rightFingerGripper from ur5e_gripper::link_2fg7_base to ur5e_gripper::rightFingerLink-->
			<joint name="13-rightFingerGripper" type="prismatic">
				<pose>0.0 -3.590717805021515E-6 -0.0052545053693176524 -1.5707499980926514 -0.0 0.0</pose>
				<parent>8-link_2fg7_base</parent>
				<child>9-rightFingerLink</child>
				<!-- WARNING: The SDF generator relies on annotations of the joint 13-rightFingerGripper to specify in SDF aspects of the joint that are
					 accounted for in the equations. -->
				<axis>
					<xyz>0 0 1</xyz>
					<dynamics>
						<damping>1000</damping>
					</dynamics>
					<limit>
						<lower>-6.2829999923706055</lower>
						<upper>6.2829999923706055</upper>
						<velocity>1</velocity>
						<effort>1000</effort>
					</limit>
				</axis>
				<!-- WARNING: Annotation not found for the actuator rightFingerMotor. RoboSim actuators have no explicit counterparts in SDF, 
					 so the generator must rely on annotations to produce something meaningful in SDF. If you wish to reflect these aspects in SDF,
					 please add an appropriate annotation to the actuator. -->
			</joint>
			<!-- Full name of joint: ur5e_gripper::wrist_2_link::wrist_3_joint from ur5e_gripper::wrist_2_link to ur5e_gripper::wrist_3_link-->
			<joint name="14-wrist_3_joint" type="revolute">
				<pose>0.0 0.03750877151316749 0.007350001424798153 0.0 1.6543612251060553E-24 0.0</pose>
				<parent>6-wrist_2_link</parent>
				<child>7-wrist_3_link</child>
				<!-- WARNING: The SDF generator relies on annotations of the joint 14-wrist_3_joint to specify in SDF aspects of the joint that are
					 accounted for in the equations. -->
				<axis>
					<xyz>0 1 0</xyz>
					<dynamics>
						<damping>10</damping>
					</dynamics>
					<limit>
						<lower>-6.2829999923706055</lower>
						<upper>6.2829999923706055</upper>
						<velocity>1.5707499980926514</velocity>
						<effort>1000</effort>
					</limit>
				</axis>
				<!-- WARNING: Annotation not found for the actuator M5. RoboSim actuators have no explicit counterparts in SDF, 
					 so the generator must rely on annotations to produce something meaningful in SDF. If you wish to reflect these aspects in SDF,
					 please add an appropriate annotation to the actuator. -->
			</joint>
			<!-- Full name of joint: ur5e_gripper::forearm_link::wrist_1_joint from ur5e_gripper::forearm_link to ur5e_gripper::wrist_1_link-->
			<joint name="15-wrist_1_joint" type="revolute">
				<pose>-9.99982973788116E-4 9.09677627183858E-8 1.821876987749549E-5 1.1070560616774092 -1.5706927326673965 -1.107148716935551</pose>
				<parent>4-forearm_link</parent>
				<child>5-wrist_1_link</child>
				<!-- WARNING: The SDF generator relies on annotations of the joint 15-wrist_1_joint to specify in SDF aspects of the joint that are
					 accounted for in the equations. -->
				<axis>
					<xyz>0 1 0</xyz>
					<dynamics>
						<damping>10</damping>
					</dynamics>
					<limit>
						<lower>-6.2829999923706055</lower>
						<upper>6.2829999923706055</upper>
						<velocity>1.5707499980926514</velocity>
						<effort>1000</effort>
					</limit>
				</axis>
				<!-- WARNING: Annotation not found for the actuator M4. RoboSim actuators have no explicit counterparts in SDF, 
					 so the generator must rely on annotations to produce something meaningful in SDF. If you wish to reflect these aspects in SDF,
					 please add an appropriate annotation to the actuator. -->
			</joint>
			<!-- Full name of joint: ur5e_gripper::upper_arm_link::elbow_joint from ur5e_gripper::upper_arm_link to ur5e_gripper::forearm_link-->
			<joint name="16-elbow_joint" type="revolute">
				<pose>1.969021275079197E-5 0.07719999738033359 -0.024999990603192246 2.0517283354985477E-21 -0.0 0.0</pose>
				<parent>3-upper_arm_link</parent>
				<child>4-forearm_link</child>
				<!-- WARNING: The SDF generator relies on annotations of the joint 16-elbow_joint to specify in SDF aspects of the joint that are
					 accounted for in the equations. -->
				<axis>
					<xyz>0 1 0</xyz>
					<dynamics>
						<damping>10</damping>
					</dynamics>
					<limit>
						<lower>-6.2829999923706055</lower>
						<upper>6.2829999923706055</upper>
						<velocity>1.5707499980926514</velocity>
						<effort>1000</effort>
					</limit>
				</axis>
				<!-- WARNING: Annotation not found for the actuator M3. RoboSim actuators have no explicit counterparts in SDF, 
					 so the generator must rely on annotations to produce something meaningful in SDF. If you wish to reflect these aspects in SDF,
					 please add an appropriate annotation to the actuator. -->
			</joint>
			<!-- Full name of joint: ur5e_gripper::base_link::shoulder_pan_joint from ur5e_gripper::base_link to ur5e_gripper::shoulder_link-->
			<joint name="17-shoulder_pan_joint" type="revolute">
				<pose>0.0 0.0 0.009641006588935852 0.0 -0.0 3.1414999961853027</pose>
				<parent>1-base_link</parent>
				<child>2-shoulder_link</child>
				<!-- WARNING: The SDF generator relies on annotations of the joint 17-shoulder_pan_joint to specify in SDF aspects of the joint that are
					 accounted for in the equations. -->
				<axis>
					<xyz>0 0 1</xyz>
					<dynamics>
						<damping>10</damping>
					</dynamics>
					<limit>
						<lower>-6.2829999923706055</lower>
						<upper>6.2829999923706055</upper>
						<velocity>1.5707499980926514</velocity>
						<effort>1000</effort>
					</limit>
				</axis>
				<!-- WARNING: Annotation not found for the actuator MS1. RoboSim actuators have no explicit counterparts in SDF, 
					 so the generator must rely on annotations to produce something meaningful in SDF. If you wish to reflect these aspects in SDF,
					 please add an appropriate annotation to the actuator. -->
			</joint>
			<!-- Full name of joint: ur5e_gripper::wrist_1_link::wrist_2_joint from ur5e_gripper::wrist_1_link to ur5e_gripper::wrist_2_link-->
			<joint name="18-wrist_2_joint" type="revolute">
				<pose>-8.617138637090349E-6 0.0027499983000136563 0.03749138435151607 0.0 1.6543612251060553E-24 0.0</pose>
				<parent>5-wrist_1_link</parent>
				<child>6-wrist_2_link</child>
				<!-- WARNING: The SDF generator relies on annotations of the joint 18-wrist_2_joint to specify in SDF aspects of the joint that are
					 accounted for in the equations. -->
				<axis>
					<xyz>0 0 -1</xyz>
					<dynamics>
						<damping>10</damping>
					</dynamics>
					<limit>
						<lower>-6.2829999923706055</lower>
						<upper>6.2829999923706055</upper>
						<velocity>1.5707499980926514</velocity>
						<effort>1000</effort>
					</limit>
				</axis>
				<!-- WARNING: Annotation not found for the actuator M5. RoboSim actuators have no explicit counterparts in SDF, 
					 so the generator must rely on annotations to produce something meaningful in SDF. If you wish to reflect these aspects in SDF,
					 please add an appropriate annotation to the actuator. -->
			</joint>
			<!-- End of joints of the pmodel ur5e_gripper -->
			
			<!-- Start of fixed connections of the pmodel ur5e_gripper -->
			<!-- fixed joint full name is ur5e_gripper::wrist_3_link::fixedJoint::ur5e_gripper::link_2fg7_base from ur5e_gripper::wrist_3_link to ur5e_gripper::link_2fg7_base -->
			<joint name="19-fixedJoint" type="fixed">
				<parent>7-wrist_3_link</parent>
				<child>8-link_2fg7_base</child>
				<axis><xyz>0 0 1</xyz></axis>
			</joint>
			<!-- End of fixed connections of the pmodel ur5e_gripper -->
		</model>
</sdf>
